2020-09-13 15:43:13,768 - [test_case_projects.py-->line:94] - INFO: 用例--创建接口_成功_名称长度1--执行成功
2020-09-13 15:43:19,742 - [test_case_projects.py-->line:94] - INFO: 用例--创建接口_成功_名称长度200--执行成功
2020-09-13 15:43:19,882 - [test_case_projects.py-->line:94] - INFO: 用例--创建接口_错误_名称长度0--执行成功
2020-09-13 15:43:20,093 - [test_case_projects.py-->line:94] - INFO: 用例--创建接口_错误_名称长度201--执行成功
2020-09-13 15:43:20,324 - [test_case_projects.py-->line:90] - ERROR: 用例--创建接口_错误_名称重复--执行失败
Traceback (most recent call last):
  File "c:\工具资料\GitHub\python_api_keyou\testcase\test_case_projects.py", line 83, in test_case
    com_assertEqual(self, respone, eval(kwargs["expect"]))
  File "c:\工具资料\GitHub\python_api_keyou\com_func\com_request_func.py", line 34, in com_assertEqual
    self.assertEqual(respone.status_code, expect["Status"])  # 判断code
  File "C:\Users\64121\AppData\Local\Programs\Python\Python37\lib\unittest\case.py", line 852, in assertEqual
    assertion_func(first, second, msg=msg)
  File "C:\Users\64121\AppData\Local\Programs\Python\Python37\lib\unittest\case.py", line 845, in _baseAssertEqual
    raise self.failureException(msg)
AssertionError: 201 != 400
2020-09-13 15:43:20,606 - [test_case_projects.py-->line:90] - ERROR: 用例--创建接口_错误_名称类型--执行失败
Traceback (most recent call last):
  File "c:\工具资料\GitHub\python_api_keyou\testcase\test_case_projects.py", line 83, in test_case
    com_assertEqual(self, respone, eval(kwargs["expect"]))
  File "c:\工具资料\GitHub\python_api_keyou\com_func\com_request_func.py", line 34, in com_assertEqual
    self.assertEqual(respone.status_code, expect["Status"])  # 判断code
  File "C:\Users\64121\AppData\Local\Programs\Python\Python37\lib\unittest\case.py", line 852, in assertEqual
    assertion_func(first, second, msg=msg)
  File "C:\Users\64121\AppData\Local\Programs\Python\Python37\lib\unittest\case.py", line 845, in _baseAssertEqual
    raise self.failureException(msg)
AssertionError: 201 != 400
2020-09-13 15:43:20,763 - [test_case_projects.py-->line:94] - INFO: 用例--创建接口_错误_名称不填--执行成功
2020-09-13 15:43:21,084 - [test_case_projects.py-->line:94] - INFO: 用例--创建接口_成功_测试人员长度50--执行成功
2020-09-13 15:43:21,297 - [test_case_projects.py-->line:94] - INFO: 用例--创建接口_错误_测试人员长度0--执行成功
2020-09-13 15:43:21,515 - [test_case_projects.py-->line:90] - ERROR: 用例--创建接口_错误_测试人员长度51--执行失败
Traceback (most recent call last):
  File "c:\工具资料\GitHub\python_api_keyou\testcase\test_case_projects.py", line 83, in test_case
    com_assertEqual(self, respone, eval(kwargs["expect"]))
  File "c:\工具资料\GitHub\python_api_keyou\com_func\com_request_func.py", line 35, in com_assertEqual
    com_assertIn(str(respone.json()), expect["msg"])  # msg
  File "c:\工具资料\GitHub\python_api_keyou\com_func\com_request_func.py", line 40, in com_assertIn
    raise AssertionError
AssertionError
2020-09-13 15:43:21,733 - [test_case_projects.py-->line:90] - ERROR: 用例--创建接口_错误_测试人员类型--执行失败
Traceback (most recent call last):
  File "c:\工具资料\GitHub\python_api_keyou\testcase\test_case_projects.py", line 83, in test_case
    com_assertEqual(self, respone, eval(kwargs["expect"]))
  File "c:\工具资料\GitHub\python_api_keyou\com_func\com_request_func.py", line 34, in com_assertEqual
    self.assertEqual(respone.status_code, expect["Status"])  # 判断code
  File "C:\Users\64121\AppData\Local\Programs\Python\Python37\lib\unittest\case.py", line 852, in assertEqual
    assertion_func(first, second, msg=msg)
  File "C:\Users\64121\AppData\Local\Programs\Python\Python37\lib\unittest\case.py", line 845, in _baseAssertEqual
    raise self.failureException(msg)
AssertionError: 201 != 400
2020-09-13 15:43:21,933 - [test_case_projects.py-->line:94] - INFO: 用例--创建接口_错误_测试人员不填--执行成功
2020-09-13 15:43:22,198 - [test_case_projects.py-->line:90] - ERROR: 用例--创建接口_错误_所属项目id不存在--执行失败
Traceback (most recent call last):
  File "c:\工具资料\GitHub\python_api_keyou\testcase\test_case_projects.py", line 83, in test_case
    com_assertEqual(self, respone, eval(kwargs["expect"]))
  File "c:\工具资料\GitHub\python_api_keyou\com_func\com_request_func.py", line 35, in com_assertEqual
    com_assertIn(str(respone.json()), expect["msg"])  # msg
  File "c:\工具资料\GitHub\python_api_keyou\com_func\com_request_func.py", line 40, in com_assertIn
    raise AssertionError
AssertionError
2020-09-13 15:43:22,423 - [test_case_projects.py-->line:90] - ERROR: 用例--创建接口_错误_所属项目id为空--执行失败
Traceback (most recent call last):
  File "c:\工具资料\GitHub\python_api_keyou\testcase\test_case_projects.py", line 83, in test_case
    com_assertEqual(self, respone, eval(kwargs["expect"]))
  File "c:\工具资料\GitHub\python_api_keyou\com_func\com_request_func.py", line 35, in com_assertEqual
    com_assertIn(str(respone.json()), expect["msg"])  # msg
  File "c:\工具资料\GitHub\python_api_keyou\com_func\com_request_func.py", line 40, in com_assertIn
    raise AssertionError
AssertionError
2020-09-13 15:43:22,633 - [test_case_projects.py-->line:94] - INFO: 用例--创建接口_错误_所属项目id不填--执行成功
2020-09-13 15:43:22,965 - [test_case_projects.py-->line:94] - INFO: 用例--创建项目_成功_简要描述长度200--执行成功
2020-09-13 15:43:23,266 - [test_case_projects.py-->line:94] - INFO: 用例--创建项目_成功_简要描述长度0--执行成功
2020-09-13 15:43:23,569 - [test_case_projects.py-->line:94] - INFO: 用例--创建项目_成功_简要描述长度为空--执行成功
