2020-09-13 16:02:35,591 - [test_case_projects.py-->line:90] - ERROR: 用例--创建接口_错误_名称重复--执行失败
Traceback (most recent call last):
  File "c:\工具资料\GitHub\python_api_keyou\testcase\test_case_projects.py", line 83, in test_case
    com_assertEqual(self, respone, eval(kwargs["expect"]))
  File "c:\工具资料\GitHub\python_api_keyou\com_func\com_request_func.py", line 35, in com_assertEqual
    com_assertIn(str(respone.json()), expect["msg"])  # msg
  File "c:\工具资料\GitHub\python_api_keyou\com_func\com_request_func.py", line 40, in com_assertIn
    raise AssertionError
AssertionError
2020-09-13 16:02:35,763 - [test_case_projects.py-->line:90] - ERROR: 用例--创建接口_错误_名称类型--执行失败
Traceback (most recent call last):
  File "c:\工具资料\GitHub\python_api_keyou\testcase\test_case_projects.py", line 83, in test_case
    com_assertEqual(self, respone, eval(kwargs["expect"]))
  File "c:\工具资料\GitHub\python_api_keyou\com_func\com_request_func.py", line 35, in com_assertEqual
    com_assertIn(str(respone.json()), expect["msg"])  # msg
  File "c:\工具资料\GitHub\python_api_keyou\com_func\com_request_func.py", line 40, in com_assertIn
    raise AssertionError
AssertionError
2020-09-13 16:02:35,907 - [test_case_projects.py-->line:94] - INFO: 用例--创建接口_错误_名称不填--执行成功
2020-09-13 16:02:36,242 - [test_case_projects.py-->line:94] - INFO: 用例--创建接口_成功_测试人员长度50--执行成功
2020-09-13 16:02:36,451 - [test_case_projects.py-->line:94] - INFO: 用例--创建接口_错误_测试人员长度0--执行成功
2020-09-13 16:02:36,667 - [test_case_projects.py-->line:94] - INFO: 用例--创建接口_错误_测试人员长度51--执行成功
2020-09-13 16:02:36,896 - [test_case_projects.py-->line:90] - ERROR: 用例--创建接口_错误_测试人员类型--执行失败
Traceback (most recent call last):
  File "c:\工具资料\GitHub\python_api_keyou\testcase\test_case_projects.py", line 83, in test_case
    com_assertEqual(self, respone, eval(kwargs["expect"]))
  File "c:\工具资料\GitHub\python_api_keyou\com_func\com_request_func.py", line 34, in com_assertEqual
    self.assertEqual(respone.status_code, expect["Status"])  # 判断code
  File "C:\Users\64121\AppData\Local\Programs\Python\Python37\lib\unittest\case.py", line 852, in assertEqual
    assertion_func(first, second, msg=msg)
  File "C:\Users\64121\AppData\Local\Programs\Python\Python37\lib\unittest\case.py", line 845, in _baseAssertEqual
    raise self.failureException(msg)
AssertionError: 201 != 400
2020-09-13 16:02:37,127 - [test_case_projects.py-->line:94] - INFO: 用例--创建接口_错误_测试人员不填--执行成功
2020-09-13 16:02:37,407 - [test_case_projects.py-->line:94] - INFO: 用例--创建接口_错误_所属项目id不存在--执行成功
2020-09-13 16:02:37,635 - [test_case_projects.py-->line:94] - INFO: 用例--创建接口_错误_所属项目id为空--执行成功
2020-09-13 16:02:37,842 - [test_case_projects.py-->line:94] - INFO: 用例--创建接口_错误_所属项目id不填--执行成功
2020-09-13 16:02:38,164 - [test_case_projects.py-->line:94] - INFO: 用例--创建项目_成功_简要描述长度200--执行成功
2020-09-13 16:02:38,474 - [test_case_projects.py-->line:94] - INFO: 用例--创建项目_成功_简要描述长度0--执行成功
2020-09-13 16:02:38,787 - [test_case_projects.py-->line:94] - INFO: 用例--创建项目_成功_简要描述长度为空--执行成功
2020-09-13 16:02:38,992 - [test_case_projects.py-->line:94] - INFO: 用例--创建项目_失败_简要描述长度201--执行成功
2020-09-13 16:03:14,967 - [test_case_projects.py-->line:94] - INFO: 用例--创建接口_成功_名称长度1--执行成功
2020-09-13 16:03:15,307 - [test_case_projects.py-->line:94] - INFO: 用例--创建接口_成功_名称长度200--执行成功
2020-09-13 16:03:15,456 - [test_case_projects.py-->line:94] - INFO: 用例--创建接口_错误_名称长度0--执行成功
2020-09-13 16:03:15,669 - [test_case_projects.py-->line:94] - INFO: 用例--创建接口_错误_名称长度201--执行成功
2020-09-13 16:03:18,780 - [test_case_projects.py-->line:94] - INFO: 用例--创建接口_错误_名称重复--执行成功
2020-09-13 16:03:18,928 - [test_case_projects.py-->line:90] - ERROR: 用例--创建接口_错误_名称类型--执行失败
Traceback (most recent call last):
  File "c:\工具资料\GitHub\python_api_keyou\testcase\test_case_projects.py", line 83, in test_case
    com_assertEqual(self, respone, eval(kwargs["expect"]))
  File "c:\工具资料\GitHub\python_api_keyou\com_func\com_request_func.py", line 35, in com_assertEqual
    com_assertIn(str(respone.json()), expect["msg"])  # msg
  File "c:\工具资料\GitHub\python_api_keyou\com_func\com_request_func.py", line 40, in com_assertIn
    raise AssertionError
AssertionError
2020-09-13 16:03:19,079 - [test_case_projects.py-->line:94] - INFO: 用例--创建接口_错误_名称不填--执行成功
2020-09-13 16:03:19,412 - [test_case_projects.py-->line:94] - INFO: 用例--创建接口_成功_测试人员长度50--执行成功
2020-09-13 16:03:19,629 - [test_case_projects.py-->line:94] - INFO: 用例--创建接口_错误_测试人员长度0--执行成功
2020-09-13 16:03:19,856 - [test_case_projects.py-->line:94] - INFO: 用例--创建接口_错误_测试人员长度51--执行成功
2020-09-13 16:03:20,096 - [test_case_projects.py-->line:90] - ERROR: 用例--创建接口_错误_测试人员类型--执行失败
Traceback (most recent call last):
  File "c:\工具资料\GitHub\python_api_keyou\testcase\test_case_projects.py", line 83, in test_case
    com_assertEqual(self, respone, eval(kwargs["expect"]))
  File "c:\工具资料\GitHub\python_api_keyou\com_func\com_request_func.py", line 34, in com_assertEqual
    self.assertEqual(respone.status_code, expect["Status"])  # 判断code
  File "C:\Users\64121\AppData\Local\Programs\Python\Python37\lib\unittest\case.py", line 852, in assertEqual
    assertion_func(first, second, msg=msg)
  File "C:\Users\64121\AppData\Local\Programs\Python\Python37\lib\unittest\case.py", line 845, in _baseAssertEqual
    raise self.failureException(msg)
AssertionError: 201 != 400
2020-09-13 16:03:20,334 - [test_case_projects.py-->line:94] - INFO: 用例--创建接口_错误_测试人员不填--执行成功
2020-09-13 16:03:20,618 - [test_case_projects.py-->line:94] - INFO: 用例--创建接口_错误_所属项目id不存在--执行成功
2020-09-13 16:03:20,843 - [test_case_projects.py-->line:94] - INFO: 用例--创建接口_错误_所属项目id为空--执行成功
2020-09-13 16:03:21,046 - [test_case_projects.py-->line:94] - INFO: 用例--创建接口_错误_所属项目id不填--执行成功
2020-09-13 16:03:21,387 - [test_case_projects.py-->line:94] - INFO: 用例--创建项目_成功_简要描述长度200--执行成功
2020-09-13 16:03:21,703 - [test_case_projects.py-->line:94] - INFO: 用例--创建项目_成功_简要描述长度0--执行成功
2020-09-13 16:03:22,014 - [test_case_projects.py-->line:94] - INFO: 用例--创建项目_成功_简要描述长度为空--执行成功
2020-09-13 16:03:22,226 - [test_case_projects.py-->line:94] - INFO: 用例--创建项目_失败_简要描述长度201--执行成功
