2020-09-06 23:44:23,004 - [test_case.py-->line:32] - ERROR: 用例--注册成功_未注册的6位账号_邮箱--执行失败
Traceback (most recent call last):
  File "c:\工具资料\GitHub\python_api_keyou\testcase\test_case.py", line 30, in test_case
    com_assertEqual(self, respone, eval(kwargs["expect"]))
  File "c:\工具资料\GitHub\python_api_keyou\com_func\com_request_func.py", line 32, in com_assertEqual
    self.assertEqual(str(respone.json()), expect["msg"])  # msg
  File "C:\Users\64121\AppData\Local\Programs\Python\Python37\lib\unittest\case.py", line 852, in assertEqual
    assertion_func(first, second, msg=msg)
  File "C:\Users\64121\AppData\Local\Programs\Python\Python37\lib\unittest\case.py", line 1233, in assertMultiLineEqual
    self.fail(self._formatMessage(msg, standardMsg))
  File "C:\Users\64121\AppData\Local\Programs\Python\Python37\lib\unittest\case.py", line 693, in fail
    raise self.failureException(msg)
AssertionError: "{'id': 90, 'username': 'C70lDw', 'token'[185 chars]Ow'}" != 'C70lDw'
- {'id': 90, 'username': 'C70lDw', 'token': 'eyJ0eXAiOiJKV1QiLCJhbGciOiJIUzI1NiJ9.eyJ1c2VyX2lkIjo5MCwidXNlcm5hbWUiOiJDNzBsRHciLCJleHAiOjE1OTk0OTM0NTcsImVtYWlsIjoiOTE3NjgzOTRAcXEuY29tIn0.Ftb1Peyva_07urpD1IHlkuW6NloGZ4lZDvhhK2jVjOw'}
+ C70lDw

